Workbook

Sheet Cover
A6: Scaled CECL Allowance for Losses Estimator (SCALE)
A12: Prepared For:
A13: ='Historical Data'!B2
A16: For Period Ending
A17: ='Calc tab'!AE6
A19: Presented by:
B35: ="© "&YEAR('Historical Data'!AY8)&" TCT Risk Solutions" | E35: ="For Period Ending "&TEXT(Cover!A17,"mm/dd/yyyy")
B36: P.O. Box 2210 | E36: =A13
B37: Eagle, ID 83616
B38: Voice (208) 939-8366 - Fax (208) 938-6276
B39: E-Mail: RThompson@tctrisk.com or Office@tctrisk.com

Sheet Introduction
B2: ='Historical Data'!B2
B3: =Cover!A6
B4: ="For Period Ending "&TEXT(Cover!A17,"mm/dd/yyyy")
B8: Introduction to the Model
C9: This report explains the anticipated loan loss exposure to the credit union using the Scaled CECL Allowance for Losses Estimator (SCALE). A credit union’s allowance account is directly related to the risk of loss resulting from non-performing loans in the portfolio. Because of this relationship, it is critical that a credit union accurately identify risk and allow for that risk in its financial statements.
C11: In a Policy Guidance Statement from 2006 the Office of Comptroller of the Currency stated:
D13: “The ALLL represents one of the most significant estimates in an institution's financial statements and regulatory reports. Because of its significance, each institution has a responsibility for developing, maintaining, and documenting a comprehensive, systematic, and consistently applied process for determining the amounts of the ALLL and the provision for loan and lease losses (PLLL). To fulfill this responsibility, each institution should ensure controls are in place to consistently determine the ALLL in accordance with GAAP, the institution's stated policies and procedures, management's best judgment and relevant supervisory guidance.”
C15: For financial institutions adopting the CECL methodology, an Allowance for Credit Losses (ACL) for loans replaces the former Allowance for Loan and Lease Losses (ALLL) referenced by the OCC. Both methodologies provide for an estimate of uncollectible amounts maintained through a valuation account adjusted through charges to operating income. The measurement framework and conceptual basis supporting an ACL differ, however, from those of the allowance for loan and lease losses.
C17: The SCALE method is one of the two methodologies offered by TCT Risk Solutions for calculating an estimate of uncollectible amounts in the loan portfolio. It was originally introduced by the Federal Reserve as a simplified application for banks. TCT has adapted this model with components of the WARM methodology to create a simple, yet statistically valid method of estimating anticipated loss in the loan portfolio.
C19: Under CECL, ACLs are estimates of the expected credit losses on financial assets measured at amortized cost, which is measured using relevant information about past events, including historical credit loss experience on financial assets with similar risk characteristics, current conditions, and reasonable and supportable forecasts that affect the collectability of the remaining cash flows over the contractual term of the financial assets.
C21: TCT pulls core data from the 5300 to populate the model in order to calculate the ACL. The credit union provides information relative to individually identified loans to include in the model for calculating the ACL. Throughout the process TCT relies on input and guidance from Credit Union management.
B27: =Cover!B35 | L27: Confidential

Sheet Scale Calculation
C2: CECL Allowances for Credit Losses (ACL) Calculation
C3: ="Prepared For "&'Historical Data'!B2
C4: ="Quarter Ended "& TEXT('Calc tab'!AE6,"m/d/yyyy")
C5: ="Charter Number "&'Historical Data'!B3
C8: Portfolio Segment | E8: End of Period Loan Balance | F8: - | G8: Less Loans Assessed on Individual Basis | H8: = | I8: Net Loans Assessed on Pooled Basis | K8: CECL ACL Lifetime Loss Rate | L8: +/- | M8: Mgmt. Adj. | N8: = | O8: Life of Loan Loss Rate | Q8: Base CECL ACL | R8: +/- | S8: Adj. for Qualitative Factors | U8: Final CECL ACL
C9: Unsecured Credit Card Loans | E9: ='Calc tab'!AE7 | G9: =SUMIF(' Impaired Loans ASC 310-10'!$D$27:$D$412,C9,' Impaired Loans ASC 310-10'!$Q$27:$Q$412) | I9: =E9-G9 | K9: ='Calc tab'!AI58 | M9: ='Historical Data'!AY145 | O9: =K9+M9 | Q9: =I9*O9 | S9: ='Env Factor by Pool'!I17 | U9: =Q9+(Q9*S9)
C10: Payday Alternative Loans | E10: ='Calc tab'!AE8 | G10: =SUMIF(' Impaired Loans ASC 310-10'!$D$27:$D$412,C10,' Impaired Loans ASC 310-10'!$Q$27:$Q$412) | I10: =E10-G10 | K10: ='Calc tab'!AI59 | M10: ='Historical Data'!AY146 | O10: =K10+M10 | Q10: =I10*O10 | S10: ='Env Factor by Pool'!I25 | U10: =Q10+(Q10*S10)
C11: Non-Federally Guaranteed Student Loans | E11: ='Calc tab'!AE9 | G11: =SUMIF(' Impaired Loans ASC 310-10'!$D$27:$D$412,C11,' Impaired Loans ASC 310-10'!$Q$27:$Q$412) | I11: =E11-G11 | K11: ='Calc tab'!AI60 | M11: ='Historical Data'!AY147 | O11: =K11+M11 | Q11: =I11*O11 | S11: ='Env Factor by Pool'!I33 | U11: =Q11+(Q11*S11)
C12: All Other Unsecured Loans/Lines of Credit | E12: ='Calc tab'!AE10 | G12: =SUMIF(' Impaired Loans ASC 310-10'!$D$27:$D$412,C12,' Impaired Loans ASC 310-10'!$Q$27:$Q$412) | I12: =E12-G12 | K12: ='Calc tab'!AI61 | M12: ='Historical Data'!AY148 | O12: =K12+M12 | Q12: =I12*O12 | S12: ='Env Factor by Pool'!I41 | U12: =Q12+(Q12*S12)
C13: New Vehicle Loans | E13: ='Calc tab'!AE11 | G13: =SUMIF(' Impaired Loans ASC 310-10'!$D$27:$D$412,C13,' Impaired Loans ASC 310-10'!$Q$27:$Q$412) | I13: =E13-G13 | K13: ='Calc tab'!AI62 | M13: ='Historical Data'!AY149 | O13: =K13+M13 | Q13: =I13*O13 | S13: ='Env Factor by Pool'!I49 | U13: =Q13+(Q13*S13)
C14: Used Vehicle Loans | E14: ='Calc tab'!AE12 | G14: =SUMIF(' Impaired Loans ASC 310-10'!$D$27:$D$412,C14,' Impaired Loans ASC 310-10'!$Q$27:$Q$412) | I14: =E14-G14 | K14: ='Calc tab'!AI63 | M14: ='Historical Data'!AY150 | O14: =K14+M14 | Q14: =I14*O14 | S14: ='Env Factor by Pool'!I57 | U14: =Q14+(Q14*S14)
C15: Leases Receivable | E15: ='Calc tab'!AE13 | G15: =SUMIF(' Impaired Loans ASC 310-10'!$D$27:$D$412,C15,' Impaired Loans ASC 310-10'!$Q$27:$Q$412) | I15: =E15-G15 | K15: ='Calc tab'!AI64 | M15: ='Historical Data'!AY151 | O15: =K15+M15 | Q15: =I15*O15 | S15: ='Env Factor by Pool'!I65 | U15: =Q15+(Q15*S15)
C16: All Other Secured Non-Real Estate Loans/Lines of Credit | E16: ='Calc tab'!AE14 | G16: =SUMIF(' Impaired Loans ASC 310-10'!$D$27:$D$412,C16,' Impaired Loans ASC 310-10'!$Q$27:$Q$412) | I16: =E16-G16 | K16: ='Calc tab'!AI65 | M16: ='Historical Data'!AY152 | O16: =K16+M16 | Q16: =I16*O16 | S16: ='Env Factor by Pool'!I73 | U16: =Q16+(Q16*S16)
C17: Loans/Lines of Credit Secured by a First Lien on a single 1- to 4-Family Residential Property | E17: ='Calc tab'!AE15 | G17: =SUMIF(' Impaired Loans ASC 310-10'!$D$27:$D$412,C17,' Impaired Loans ASC 310-10'!$Q$27:$Q$412) | I17: =E17-G17 | K17: ='Calc tab'!AI66 | M17: ='Historical Data'!AY153 | O17: =K17+M17 | Q17: =I17*O17 | S17: ='Env Factor by Pool'!I81 | U17: =Q17+(Q17*S17)
C18: Loans/Lines of Credit Secured by a Junior Lien on a single 1- to 4-Family Residential Property | E18: ='Calc tab'!AE16 | G18: =SUMIF(' Impaired Loans ASC 310-10'!$D$27:$D$412,C18,' Impaired Loans ASC 310-10'!$Q$27:$Q$412) | I18: =E18-G18 | K18: ='Calc tab'!AI67 | M18: ='Historical Data'!AY154 | O18: =K18+M18 | Q18: =I18*O18 | S18: ='Env Factor by Pool'!I89 | U18: =Q18+(Q18*S18)
C19: All Other (Non-Commercial) Real Estate Loans/Lines of Credit | E19: ='Calc tab'!AE17 | G19: =SUMIF(' Impaired Loans ASC 310-10'!$D$27:$D$412,C19,' Impaired Loans ASC 310-10'!$Q$27:$Q$412) | I19: =E19-G19 | K19: ='Calc tab'!AI68 | M19: ='Historical Data'!AY155 | O19: =K19+M19 | Q19: =I19*O19 | S19: ='Env Factor by Pool'!I97 | U19: =Q19+(Q19*S19)
C20: Commercial Loans/Lines of Credit Real Estate Secured | E20: ='Calc tab'!AE18 | G20: =SUMIF(' Impaired Loans ASC 310-10'!$D$27:$D$412,C20,' Impaired Loans ASC 310-10'!$Q$27:$Q$412) | I20: =E20-G20 | K20: ='Calc tab'!AI69 | M20: ='Historical Data'!AY156 | O20: =K20+M20 | Q20: =I20*O20 | S20: ='Env Factor by Pool'!I145 | U20: =Q20+(Q20*S20)
C21: Commercial Loans/Lines of Credit Not Real Estate Secured | E21: ='Calc tab'!AE19 | G21: =SUMIF(' Impaired Loans ASC 310-10'!$D$27:$D$412,C21,' Impaired Loans ASC 310-10'!$Q$27:$Q$412) | I21: =E21-G21 | K21: ='Calc tab'!AI70 | M21: ='Historical Data'!AY157 | O21: =K21+M21 | Q21: =I21*O21 | S21: ='Env Factor by Pool'!I153 | U21: =Q21+(Q21*S21)
C23: Total | E23: =SUM(E9:E21) | I23: =SUM(I9:I21) | Q23: =SUM(Q9:$Q$21) | U23: =SUM(U9:U21)
Q25: Management Adjustment-Additional Environmental Factor | S25: ='Historical Data'!AY159 | U25: =I23*S25
Q27: Expected Losses on Loans Assessed on Individual Basis | U27: =' Impaired Loans ASC 310-10'!P24
Q29: Total Expected Losses on Loans | U29: =U23+U25+U27
Q30: Current ACL Balance | U30: ='Historical Data'!AY177
Q31: Adjustment | U31: =U29-U30
Q33: ACL/Total Loans | U33: =IF(U29=0,0,U29/E23)
C37: Explanation of ACL Calculation
C39: The calculation of the credit union’s ACL includes multiple components that combine to create a valid estimate of anticipated losses over the remaining life of loans in the portfolio. Those components as shown in the report above.
C41: Portfolio Segment: Loans are presented in groups, or pools, consistent with the presentation on the quarterly NCUA 5300 Call Report in this column.
C43: End of Period Loan Balance: Loan balances for each identified pool as shown in the NCUA 5300 Call reports for the end of the most recent quarter are listed in this column.
C45: Loans Assessed on Individual Basis: Loan that have been identified by credit union management as deteriorated in credit quality are listed by pool in this column.
C47: Loans Assessed on Pooled Basis: Individually assessed loans are subtracted from the End of Period loan balances for each pool and are displayed in this column.
C49: CECL ACL Lifetime Loss Rate: Based on the remaining life of loan for each loan pool, total losses for the period are summed for each pool and then divided by the average balance for the life period to arrive at a loss rate for each pool. These loss rates are shown in this column.
C51: Management Adjustment: Any adjustments to the loss rates for any pool, indicated by management judgement, are shown in this column.
C53: Life of Loan Loss Rate: The Lifetime Loss Rate and the Management Adjustments for each pool are totaled and displayed in this column.
C55: CECL ACL Base: The loss rate is multiplied times the Loans Assessed on Individual Basis to calculate the base ACL for each pool. The dollar amounts are shown in this column.
C57: Adjustment for Qualitative Factors: Two statistically validated Qualitative Factors are included in the model, advanced delinquency, and Environmental Stress Score. These factors are displayed for each pool on page 4. The indicated adjustment percentage for each pool is displayed in this column.
C59: CECL ACL Final: The Adjustment for Qualitative Factors percentage is multiplied by the CECL ALC base the resulting amount is added to the base to arrive at the CECL ACL Final. Dollar amounts for each pool is shown in this column.
... C71: ACL/Total Loans: This cells shows the percentage of total loan portfolio that is indicated in the ACL.
B77: =Cover!B35 | U77: Confidential

Sheet Env Factor by Pool
B1: ='Historical Data'!B2
B2: Environmental Factor for PLL
B3: ="For Period Ending "&TEXT('Historical Data'!AY8,"mm/dd/yyyy")
B5: Economic Stress Index Calculation
B6: State | C6: Unemployment Rate* | D6: Foreclosures per Person** | E6: Bankruptcies*** | F6: Population***
B7: ='Historical Data'!B4 | C7: ='Historical Data'!AY139 | D7: ='Historical Data'!AY140 | E7: ='Historical Data'!AY141 | F7: ='Historical Data'!AY142
B8: County | C8: Unemployment Rate | D8: Bankruptcy Percentage | E8: Foreclosure Percentage | F8: Economic Stress Index
B9: ='Historical Data'!B5 | C9: =C7 | D9: =E7/F7 | E9: =1/D7 | F9: =SUM(C9:E9)
B11: ='Scale Calculation'!C9
B12: Delinquency Variance | E12: Economic Stress
B13: Variance from Average | C13: Score | E13: Actual | F13: Score
B14: ='Calc tab'!AI92 | C14: =IF(B14>='Environmental Factor Ranges'!$J$9,'Environmental Factor Ranges'!$K$9,IF(B14>='Environmental Factor Ranges'!$J$10,'Environmental Factor Ranges'!$K$10,IF(B14>='Environmental Factor Ranges'!$J$11,'Environmental Factor Ranges'!$K$11,IF(B14>='Environmental Factor Ranges'!$J$12,'Environmental Factor Ranges'!$K$12,IF(B14>='Environmental Factor Ranges'!$J$13,'Environmental Factor Ranges'!$K$13,IF(B14>='Environmental Factor Ranges'!$J$14,'Environmental Factor Ranges'!$K$14,IF(B14>='Environmental Factor Ranges'!$J$15,'Environmental Factor Ranges'!$K$15,IF(B14>='Environmental Factor Ranges'!$J$16,'Environmental Factor Ranges'!$K$16,IF(B14>='Environmental Factor Ranges'!$J$17,'Environmental Factor Ranges'!$K$17,IF(B14>='Environmental Factor Ranges'!$J$18,'Environmental Factor Ranges'!$K$18,IF(B14>='Environmental Factor Ranges'!$J$19,'Environmental Factor Ranges'!$K$19,IF(B14>='Environmental Factor Ranges'!$J$20,'Environmental Factor Ranges'!$K$20,IF(B14>='Environmental Factor Ranges'!$J$21,'Environmental Factor Ranges'!$K$21,IF(B14>='Environmental Factor Ranges'!$J$22,'Environmental Factor Ranges'!$K$22,IF(B14>='Environmental Factor Ranges'!$J$23,'Environmental Factor Ranges'!$K$23,IF(B14>='Environmental Factor Ranges'!$J$24,'Environmental Factor Ranges'!$K$24,'Environmental Factor Ranges'!$K$25)))))))))))))))) | E14: =$F$9 | F14: =IF(E14>='Environmental Factor Ranges'!$L$9,'Environmental Factor Ranges'!$F$9,IF(E14>='Environmental Factor Ranges'!$L$10,'Environmental Factor Ranges'!$F$10,IF(E14>='Environmental Factor Ranges'!$L$11,'Environmental Factor Ranges'!$F$11,IF(E14>='Environmental Factor Ranges'!$L$12,'Environmental Factor Ranges'!$F$12,IF(E14>='Environmental Factor Ranges'!$L$13,'Environmental Factor Ranges'!$F$13,IF(E14>='Environmental Factor Ranges'!$L$14,'Environmental Factor Ranges'!$F$14,IF(E14>='Environmental Factor Ranges'!$L$15,'Environmental Factor Ranges'!$F$15,IF(E14>='Environmental Factor Ranges'!$L$16,'Environmental Factor Ranges'!$F$16,IF(E14>='Environmental Factor Ranges'!$L$17,'Environmental Factor Ranges'!$F$17,IF(E14>='Environmental Factor Ranges'!$L$18,'Environmental Factor Ranges'!$F$18,IF(E14>='Environmental Factor Ranges'!$L$19,'Environmental Factor Ranges'!$F$19,IF(E14>='Environmental Factor Ranges'!$L$20,'Environmental Factor Ranges'!$F$20,IF(E14>='Environmental Factor Ranges'!$L$21,'Environmental Factor Ranges'!$F$21,IF(E14>='Environmental Factor Ranges'!$L$22,'Environmental Factor Ranges'!$F$22,IF(E14>='Environmental Factor Ranges'!$L$23,'Environmental Factor Ranges'!$F$23,IF(E14>='Environmental Factor Ranges'!$L$24,'Environmental Factor Ranges'!$F$24,IF(E14>='Environmental Factor Ranges'!$L$25,'Environmental Factor Ranges'!$F$25,'Environmental Factor Ranges'!$F$26)))))))))))))))))
B15: ="Environmental Factor-"&B11
B16: =C14+F14
H17: Environmental Factor | I17: =B16
B19: ='Scale Calculation'!C10
B20: =$B$12 | E20: Economic Stress
B21: =B13 | C21: Score | E21: Actual | F21: Score
B22: ='Calc tab'!AI93 | C22: =IF(B22>='Environmental Factor Ranges'!$J$9,'Environmental Factor Ranges'!$K$9,IF(B22>='Environmental Factor Ranges'!$J$10,'Environmental Factor Ranges'!$K$10,IF(B22>='Environmental Factor Ranges'!$J$11,'Environmental Factor Ranges'!$K$11,IF(B22>='Environmental Factor Ranges'!$J$12,'Environmental Factor Ranges'!$K$12,IF(B22>='Environmental Factor Ranges'!$J$13,'Environmental Factor Ranges'!$K$13,IF(B22>='Environmental Factor Ranges'!$J$14,'Environmental Factor Ranges'!$K$14,IF(B22>='Environmental Factor Ranges'!$J$15,'Environmental Factor Ranges'!$K$15,IF(B22>='Environmental Factor Ranges'!$J$16,'Environmental Factor Ranges'!$K$16,IF(B22>='Environmental Factor Ranges'!$J$17,'Environmental Factor Ranges'!$K$17,IF(B22>='Environmental Factor Ranges'!$J$18,'Environmental Factor Ranges'!$K$18,IF(B22>='Environmental Factor Ranges'!$J$19,'Environmental Factor Ranges'!$K$19,IF(B22>='Environmental Factor Ranges'!$J$20,'Environmental Factor Ranges'!$K$20,IF(B22>='Environmental Factor Ranges'!$J$21,'Environmental Factor Ranges'!$K$21,IF(B22>='Environmental Factor Ranges'!$J$22,'Environmental Factor Ranges'!$K$22,IF(B22>='Environmental Factor Ranges'!$J$23,'Environmental Factor Ranges'!$K$23,IF(B22>='Environmental Factor Ranges'!$J$24,'Environmental Factor Ranges'!$K$24,'Environmental Factor Ranges'!$K$25)))))))))))))))) | E22: =$F$9 | F22: =IF(E22>='Environmental Factor Ranges'!$L$9,'Environmental Factor Ranges'!$F$9,IF(E22>='Environmental Factor Ranges'!$L$10,'Environmental Factor Ranges'!$F$10,IF(E22>='Environmental Factor Ranges'!$L$11,'Environmental Factor Ranges'!$F$11,IF(E22>='Environmental Factor Ranges'!$L$12,'Environmental Factor Ranges'!$F$12,IF(E22>='Environmental Factor Ranges'!$L$13,'Environmental Factor Ranges'!$F$13,IF(E22>='Environmental Factor Ranges'!$L$14,'Environmental Factor Ranges'!$F$14,IF(E22>='Environmental Factor Ranges'!$L$15,'Environmental Factor Ranges'!$F$15,IF(E22>='Environmental Factor Ranges'!$L$16,'Environmental Factor Ranges'!$F$16,IF(E22>='Environmental Factor Ranges'!$L$17,'Environmental Factor Ranges'!$F$17,IF(E22>='Environmental Factor Ranges'!$L$18,'Environmental Factor Ranges'!$F$18,IF(E22>='Environmental Factor Ranges'!$L$19,'Environmental Factor Ranges'!$F$19,IF(E22>='Environmental Factor Ranges'!$L$20,'Environmental Factor Ranges'!$F$20,'Environmental Factor Ranges'!$F$21))))))))))))
B23: ="Environmental Factor-"&B19
B24: =C22+F22
H25: Environmental Factor | I25: =B24
B27: ='Scale Calculation'!C11
B28: =$B$12 | E28: Economic Stress
B29: =B13 | C29: Score | E29: Actual | F29: Score
B30: ='Calc tab'!AI94 | C30: =IF(B30>='Environmental Factor Ranges'!$J$9,'Environmental Factor Ranges'!$K$9,IF(B30>='Environmental Factor Ranges'!$J$10,'Environmental Factor Ranges'!$K$10,IF(B30>='Environmental Factor Ranges'!$J$11,'Environmental Factor Ranges'!$K$11,IF(B30>='Environmental Factor Ranges'!$J$12,'Environmental Factor Ranges'!$K$12,IF(B30>='Environmental Factor Ranges'!$J$13,'Environmental Factor Ranges'!$K$13,IF(B30>='Environmental Factor Ranges'!$J$14,'Environmental Factor Ranges'!$K$14,IF(B30>='Environmental Factor Ranges'!$J$15,'Environmental Factor Ranges'!$K$15,IF(B30>='Environmental Factor Ranges'!$J$16,'Environmental Factor Ranges'!$K$16,IF(B30>='Environmental Factor Ranges'!$J$17,'Environmental Factor Ranges'!$K$17,IF(B30>='Environmental Factor Ranges'!$J$18,'Environmental Factor Ranges'!$K$18,IF(B30>='Environmental Factor Ranges'!$J$19,'Environmental Factor Ranges'!$K$19,IF(B30>='Environmental Factor Ranges'!$J$20,'Environmental Factor Ranges'!$K$20,IF(B30>='Environmental Factor Ranges'!$J$21,'Environmental Factor Ranges'!$K$21,IF(B30>='Environmental Factor Ranges'!$J$22,'Environmental Factor Ranges'!$K$22,IF(B30>='Environmental Factor Ranges'!$J$23,'Environmental Factor Ranges'!$K$23,IF(B30>='Environmental Factor Ranges'!$J$24,'Environmental Factor Ranges'!$K$24,'Environmental Factor Ranges'!$K$25)))))))))))))))) | E30: =$F$9 | F30: =IF(E30>='Environmental Factor Ranges'!$L$9,'Environmental Factor Ranges'!$F$9,IF(E30>='Environmental Factor Ranges'!$L$10,'Environmental Factor Ranges'!$F$10,IF(E30>='Environmental Factor Ranges'!$L$11,'Environmental Factor Ranges'!$F$11,IF(E30>='Environmental Factor Ranges'!$L$12,'Environmental Factor Ranges'!$F$12,IF(E30>='Environmental Factor Ranges'!$L$13,'Environmental Factor Ranges'!$F$13,IF(E30>='Environmental Factor Ranges'!$L$14,'Environmental Factor Ranges'!$F$14,IF(E30>='Environmental Factor Ranges'!$L$15,'Environmental Factor Ranges'!$F$15,IF(E30>='Environmental Factor Ranges'!$L$16,'Environmental Factor Ranges'!$F$16,IF(E30>='Environmental Factor Ranges'!$L$17,'Environmental Factor Ranges'!$F$17,IF(E30>='Environmental Factor Ranges'!$L$18,'Environmental Factor Ranges'!$F$18,IF(E30>='Environmental Factor Ranges'!$L$19,'Environmental Factor Ranges'!$F$19,IF(E30>='Environmental Factor Ranges'!$L$20,'Environmental Factor Ranges'!$F$20,'Environmental Factor Ranges'!$F$21))))))))))))
B31: ="Environmental Factor-"&B27
B32: =C30+F30
H33: Environmental Factor | I33: =B32
B35: ='Scale Calculation'!C12
B36: =$B$12 | E36: Economic Stress
B37: =B21 | C37: Score | E37: Actual | F37: Score
B38: ='Calc tab'!AI95 | C38: =IF(B38>='Environmental Factor Ranges'!$J$9,'Environmental Factor Ranges'!$K$9,IF(B38>='Environmental Factor Ranges'!$J$10,'Environmental Factor Ranges'!$K$10,IF(B38>='Environmental Factor Ranges'!$J$11,'Environmental Factor Ranges'!$K$11,IF(B38>='Environmental Factor Ranges'!$J$12,'Environmental Factor Ranges'!$K$12,IF(B38>='Environmental Factor Ranges'!$J$13,'Environmental Factor Ranges'!$K$13,IF(B38>='Environmental Factor Ranges'!$J$14,'Environmental Factor Ranges'!$K$14,IF(B38>='Environmental Factor Ranges'!$J$15,'Environmental Factor Ranges'!$K$15,IF(B38>='Environmental Factor Ranges'!$J$16,'Environmental Factor Ranges'!$K$16,IF(B38>='Environmental Factor Ranges'!$J$17,'Environmental Factor Ranges'!$K$17,IF(B38>='Environmental Factor Ranges'!$J$18,'Environmental Factor Ranges'!$K$18,IF(B38>='Environmental Factor Ranges'!$J$19,'Environmental Factor Ranges'!$K$19,IF(B38>='Environmental Factor Ranges'!$J$20,'Environmental Factor Ranges'!$K$20,IF(B38>='Environmental Factor Ranges'!$J$21,'Environmental Factor Ranges'!$K$21,IF(B38>='Environmental Factor Ranges'!$J$22,'Environmental Factor Ranges'!$K$22,IF(B38>='Environmental Factor Ranges'!$J$23,'Environmental Factor Ranges'!$K$23,IF(B38>='Environmental Factor Ranges'!$J$24,'Environmental Factor Ranges'!$K$24,'Environmental Factor Ranges'!$K$25)))))))))))))))) | E38: =$F$9 | F38: =IF(E38>='Environmental Factor Ranges'!$L$9,'Environmental Factor Ranges'!$F$9,IF(E38>='Environmental Factor Ranges'!$L$10,'Environmental Factor Ranges'!$F$10,IF(E38>='Environmental Factor Ranges'!$L$11,'Environmental Factor Ranges'!$F$11,IF(E38>='Environmental Factor Ranges'!$L$12,'Environmental Factor Ranges'!$F$12,IF(E38>='Environmental Factor Ranges'!$L$13,'Environmental Factor Ranges'!$F$13,IF(E38>='Environmental Factor Ranges'!$L$14,'Environmental Factor Ranges'!$F$14,IF(E38>='Environmental Factor Ranges'!$L$15,'Environmental Factor Ranges'!$F$15,IF(E38>='Environmental Factor Ranges'!$L$16,'Environmental Factor Ranges'!$F$16,IF(E38>='Environmental Factor Ranges'!$L$17,'Environmental Factor Ranges'!$F$17,IF(E38>='Environmental Factor Ranges'!$L$18,'Environmental Factor Ranges'!$F$18,IF(E38>='Environmental Factor Ranges'!$L$19,'Environmental Factor Ranges'!$F$19,IF(E38>='Environmental Factor Ranges'!$L$20,'Environmental Factor Ranges'!$F$20,'Environmental Factor Ranges'!$F$21))))))))))))
B39: ="Environmental Factor-"&B35
B40: =C38+F38
H41: Environmental Factor | I41: =B40
B43: ='Scale Calculation'!C13
B44: =$B$12 | E44: Economic Stress
B45: =B13 | C45: Score | E45: Actual | F45: Score
B46: ='Calc tab'!AI96 | C46: =IF(B46>='Environmental Factor Ranges'!$J$9,'Environmental Factor Ranges'!$K$9,IF(B46>='Environmental Factor Ranges'!$J$10,'Environmental Factor Ranges'!$K$10,IF(B46>='Environmental Factor Ranges'!$J$11,'Environmental Factor Ranges'!$K$11,IF(B46>='Environmental Factor Ranges'!$J$12,'Environmental Factor Ranges'!$K$12,IF(B46>='Environmental Factor Ranges'!$J$13,'Environmental Factor Ranges'!$K$13,IF(B46>='Environmental Factor Ranges'!$J$14,'Environmental Factor Ranges'!$K$14,IF(B46>='Environmental Factor Ranges'!$J$15,'Environmental Factor Ranges'!$K$15,IF(B46>='Environmental Factor Ranges'!$J$16,'Environmental Factor Ranges'!$K$16,IF(B46>='Environmental Factor Ranges'!$J$17,'Environmental Factor Ranges'!$K$17,IF(B46>='Environmental Factor Ranges'!$J$18,'Environmental Factor Ranges'!$K$18,IF(B46>='Environmental Factor Ranges'!$J$19,'Environmental Factor Ranges'!$K$19,IF(B46>='Environmental Factor Ranges'!$J$20,'Environmental Factor Ranges'!$K$20,IF(B46>='Environmental Factor Ranges'!$J$21,'Environmental Factor Ranges'!$K$21,IF(B46>='Environmental Factor Ranges'!$J$22,'Environmental Factor Ranges'!$K$22,IF(B46>='Environmental Factor Ranges'!$J$23,'Environmental Factor Ranges'!$K$23,IF(B46>='Environmental Factor Ranges'!$J$24,'Environmental Factor Ranges'!$K$24,'Environmental Factor Ranges'!$K$25)))))))))))))))) | E46: =$F$9 | F46: =IF(E46>='Environmental Factor Ranges'!$L$9,'Environmental Factor Ranges'!$F$9,IF(E46>='Environmental Factor Ranges'!$L$10,'Environmental Factor Ranges'!$F$10,IF(E46>='Environmental Factor Ranges'!$L$11,'Environmental Factor Ranges'!$F$11,IF(E46>='Environmental Factor Ranges'!$L$12,'Environmental Factor Ranges'!$F$12,IF(E46>='Environmental Factor Ranges'!$L$13,'Environmental Factor Ranges'!$F$13,IF(E46>='Environmental Factor Ranges'!$L$14,'Environmental Factor Ranges'!$F$14,IF(E46>='Environmental Factor Ranges'!$L$15,'Environmental Factor Ranges'!$F$15,IF(E46>='Environmental Factor Ranges'!$L$16,'Environmental Factor Ranges'!$F$16,IF(E46>='Environmental Factor Ranges'!$L$17,'Environmental Factor Ranges'!$F$17,IF(E46>='Environmental Factor Ranges'!$L$18,'Environmental Factor Ranges'!$F$18,IF(E46>='Environmental Factor Ranges'!$L$19,'Environmental Factor Ranges'!$F$19,IF(E46>='Environmental Factor Ranges'!$L$20,'Environmental Factor Ranges'!$F$20,'Environmental Factor Ranges'!$F$21))))))))))))
...

Sheet Environmental Factor Ranges
B2: ='Historical Data'!B2
B3: Environmental Factor Ranges
B4: ="For Period Ending "&TEXT('Historical Data'!AY8,"mm/dd/yyyy")
O5: TCT Risk Solutions conducts regular reviews of data to support its CECL methodology and calculations. These analytics include multiple regression analysis, Cluster Analysis, t-tests, MANOVA and Variance analysis.
B6: Environmental Factor Scale Table | O6: Based on the most recent analysis, we have identified changes that are indicated in the Economic Stress score employed as an Environmental Factor in our CECL methodology. The changes are as follows:
B7: Delinquency | E7: Economic Stress Score | J7: Delinquency | L7: Economic stress
C8: Range | D8: Score | E8: Range | F8: Score | J8: Minimums | K8: Score | L8: Minimums | M8: Score | P8: Range | R8: Score
C9: =IF(J9=0,"Not Risk Rated",">"&TEXT(J9,"#.00%")) | D9: =K9 | E9: =">"&TEXT(L9,"#.00%") | F9: =M9 | J9: 0.05 | K9: 0.2 | L9: 0.25 | M9: 0.1 | P9: >25% | R9: 0.1
C10: =TEXT(J10,"#.00%")&" to "&TEXT(J9-0.0001,"#.00%") | D10: =K10 | E10: =TEXT(L10,"#.00%")&" to "&TEXT(L9-0.0001,"#.00%") | F10: =M10 | J10: 0.04 | K10: 0.17 | L10: 0.24 | M10: 0.08 | O10: 0.24 | P10: 0.2499 | R10: 0.08
C11: =TEXT(J11,"#.00%")&" to "&TEXT(J10-0.0001,"#.00%") | D11: =K11 | E11: =TEXT(L11,"#.00%")&" to "&TEXT(L10-0.0001,"#.00%") | F11: =M11 | J11: 0.03 | K11: 0.12 | L11: 0.22 | M11: 0.07 | O11: 0.22 | P11: 0.2399 | R11: 0.07
C12: =TEXT(J12,"#.00%")&" to "&TEXT(J11-0.0001,"#.00%") | D12: =K12 | E12: =TEXT(L12,"#.00%")&" to "&TEXT(L11-0.0001,"#.00%") | F12: =M12 | J12: 0.025 | K12: 0.08 | L12: 0.2 | M12: 0.06 | O12: 0.2 | P12: 0.2199 | R12: 0.06
C13: =TEXT(J13,"#.00%")&" to "&TEXT(J12-0.0001,"#.00%") | D13: =K13 | E13: =TEXT(L13,"#.00%")&" to "&TEXT(L12-0.0001,"#.00%") | F13: =M13 | J13: 0.02 | K13: 0.04 | L13: 0.18 | M13: 0.05 | O13: 0.18 | P13: 0.1999 | R13: 0.05
C14: =TEXT(J14,"#.00%")&" to "&TEXT(J13-0.0001,"#.00%") | D14: =K14 | E14: =TEXT(L14,"#.00%")&" to "&TEXT(L13-0.0001,"#.00%") | F14: =M14 | J14: 0.015 | K14: 0.025 | L14: 0.16 | M14: 0.04 | O14: 0.16 | P14: 0.1799 | R14: 0.04
C15: =TEXT(J15,"#.00%")&" to "&TEXT(J14-0.0001,"#.00%") | D15: =K15 | E15: =TEXT(L15,"#.00%")&" to "&TEXT(L14-0.0001,"#.00%") | F15: =M15 | J15: 0.01 | K15: 0.015 | L15: 0.14 | M15: 0.035 | O15: 0.14 | P15: 0.1599 | R15: 0.035
C16: =TEXT(J16,"#.00%")&" to "&TEXT(J15-0.0001,"#.00%") | D16: =K16 | E16: =TEXT(L16,"#.00%")&" to "&TEXT(L15-0.0001,"#.00%") | F16: =M16 | J16: 0.005 | K16: 0.0075 | L16: 0.12 | M16: 0.03 | O16: 0.12 | P16: 0.1399 | R16: 0.03
C17: =TEXT(J17,"#.00%")&" to "&TEXT(J16-0.0001,"#.00%") | D17: =K17 | E17: =TEXT(L17,"#.00%")&" to "&TEXT(L16-0.0001,"#.00%") | F17: =M17 | J17: -0.0049 | K17: 0 | L17: 0.1 | M17: 0.02 | O17: 0.1 | P17: 0.1199 | R17: 0.02
C18: =TEXT(J18,"#.00%")&" to "&TEXT(J17-0.0001,"#.00%") | D18: =K18 | E18: =TEXT(L18,"#.00%")&" to "&TEXT(L17-0.0001,"#.00%") | F18: =M18 | J18: -0.0099 | K18: -0.0075 | L18: 0.08 | M18: 0.01 | O18: 0.08 | P18: 0.0999 | R18: 0.01
C19: =TEXT(J19,"#.00%")&" to "&TEXT(J18-0.0001,"#.00%") | D19: =K19 | E19: =TEXT(L19,"#.00%")&" to "&TEXT(L18-0.0001,"#.00%") | F19: =M19 | J19: -0.0149 | K19: -0.015 | L19: 0.06 | M19: 0 | O19: 0.06 | P19: 0.0799 | R19: 0
C20: =TEXT(J20,"#.00%")&" to "&TEXT(J19-0.0001,"#.00%") | D20: =K20 | E20: =TEXT(L20,"#.00%")&" to "&TEXT(L19-0.0001,"#.00%") | F20: =M20 | J20: -0.0199 | K20: -0.025 | L20: 0.04 | M20: 0 | O20: 0.04 | P20: 0.0599 | R20: 0
C21: =TEXT(J21,"#.00%")&" to "&TEXT(J20-0.0001,"#.00%") | D21: =K21 | E21: =TEXT(L21,"#.00%")&" to "&TEXT(L20-0.0001,"#.00%") | F21: =M21 | J21: -0.0249 | K21: -0.04 | L21: 0.02 | M21: -0.01 | O21: 0.02 | P21: 0.0399 | R21: -0.01
C22: =TEXT(J22,"#.00%")&" to "&TEXT(J21-0.0001,"#.00%") | D22: =K22 | E22: =TEXT(L22,"#.00%")&" to "&TEXT(L21-0.0001,"#.00%") | F22: =M22 | J22: -0.0299 | K22: -0.08 | L22: 0 | M22: -0.02 | O22: 0 | P22: 0.0199 | R22: -0.02
C23: =TEXT(J23,"#.00%")&" to "&TEXT(J22-0.0001,"#.00%") | D23: =K23 | J23: -0.0399 | K23: -0.12
C24: =TEXT(J24,"#.00%")&" to "&TEXT(J23-0.0001,"#.00%") | D24: =K24 | J24: -0.0499 | K24: -0.17 | O24: These changes will take affect as of September 30, 2025.
C25: =IF(J25=0,"Not Risk Rated","<"&TEXT(J25,"#.00%")) | D25: =K25 | J25: -0.05 | K25: -0.2
C29: Discussion of Environmental Factor
C31: The Environmental Factor combines two distinct data sets to calculate the likely variance between the historical loss rate and the anticipated loss rate. As these two data sets improve the likelihood of loss decreases and as they deteriorate the likelihood of loss increases, hence the need to adjust the pool provision. Statistical tests including regression, MANOVA and Pearson 'R (correlation) were employed to validate each Factor and to establish the ranges.
C33: GAAP states that “when estimating credit losses on each group of loans with similar risk characteristics, an institution should consider its historical loss experience on the group, adjusted for changes in trends, conditions, and other relevant factors that affect repayment of the loans as of the evaluation date.”
C35: As part of the SCALE methodology, the Environmental Factor, or Q&E, is used to adjust the pooled loan allowance to assure it is representative of current risk. Two measures, identified in the Comptrollers Handbook, (e.g., delinquency and economic stress factor) are correlated to the charge-off history of the credit union, to determine if an adjustment to the pool risk factors are indicated. The two measures are applied to minimize the potential for skewing that could result from a single measure. Using accepted statistical techniques, (e.g., regression, ANOVA and correlation) the extent of the relationship is measured, and the adjustment is applied to the Pooled allowance amount for each grade to arrive at the adjusted allowance amount.
C37: Delinquency:
C39: A running history of the Reported Delinquency is pulled and maintained by TCT. Using this delinquency database, a trend is created to indicate the directionality of credit union past due loans over the indicated Life of Loan period for each pool. This trend of the Life of Loans DQ rates are compared to the current period DQ rate to determine if the rate is improving or deteriorating. An improving rate indicates lower risk of loss while a deteriorating rate indicated a higher risk of loss.
C41: Economic Stress Score:
C43: Measures the relative impact of the local economy on the historical loss rate. Calculated using Unemployment Rate, Bankruptcy Percentage, Foreclosure Rates and Population statistics for the State in which the Credit Union is based. The sources of these figures are: The Bureau of Labor Statistics, Realty Trac, and Electronic Access to Federal Court Records.
B49: =Cover!B35 | G49: Confidential

Sheet  Impaired Loans ASC 310-10
A1: ='Historical Data'!B2
A2: Impaired Loans Loans Report
A3: Report for Period Ending | B3: ='Historical Data'!AY8
A4: Impairment Type | B4: Provision Percentage | L4: =A4 | N4: ="Sum of "&N27 | P4: ="Sum of "&P27 | Q4: ="Sum of "&Q27
A5: Delinquent Loans | B5: 0.25 | L5: =IF(A5=0,"",A5) | N5: =IF(A5=0,"",SUMIF($A$28:$A$412,L5,$N$28:$N$412)) | P5: =IF(A5=0,"",SUMIF($A$28:$A$412,L5,$P$28:$P$412)) | Q5: =IF(A5=0,"",SUMIF($A$28:$A$412,L5,$Q$28:$Q$412))
A6: Known Losses | B6: 1 | L6: =IF(A6=0,"",A6) | N6: =IF(A6=0,"",SUMIF($A$28:$A$412,L6,$N$28:$N$412)) | P6: =IF(A6=0,"",SUMIF($A$28:$A$412,L6,$P$28:$P$412)) | Q6: =IF(A6=0,"",SUMIF($A$28:$A$412,L6,$Q$28:$Q$412))
A7: Repossessions | B7: 1 | L7: =IF(A7=0,"",A7) | N7: =IF(A7=0,"",SUMIF($A$28:$A$412,L7,$N$28:$N$412)) | P7: =IF(A7=0,"",SUMIF($A$28:$A$412,L7,$P$28:$P$412)) | Q7: =IF(A7=0,"",SUMIF($A$28:$A$412,L7,$Q$28:$Q$412))
A8: Foreclosed Real Estate | B8: 1 | L8: =IF(A8=0,"",A8) | N8: =IF(A8=0,"",SUMIF($A$28:$A$412,L8,$N$28:$N$412)) | P8: =IF(A8=0,"",SUMIF($A$28:$A$412,L8,$P$28:$P$412)) | Q8: =IF(A8=0,"",SUMIF($A$28:$A$412,L8,$Q$28:$Q$412))
A9: Other Individually Identified Loans | B9: 1 | L9: =IF(A9=0,"",A9) | N9: =IF(A9=0,"",SUMIF($A$28:$A$412,L9,$N$28:$N$412)) | P9: =IF(A9=0,"",SUMIF($A$28:$A$412,L9,$P$28:$P$412)) | Q9: =IF(A9=0,"",SUMIF($A$28:$A$412,L9,$Q$28:$Q$412))
L10: =IF(A10=0,"",A10) | N10: =IF(A10=0,"",SUMIF($A$28:$A$412,L10,$N$28:$N$412)) | P10: =IF(A10=0,"",SUMIF($A$28:$A$412,L10,$P$28:$P$412)) | Q10: =IF(A10=0,"",SUMIF($A$28:$A$412,L10,$Q$28:$Q$412))
L11: =IF(A11=0,"",A11) | N11: =IF(A11=0,"",SUMIF($A$28:$A$412,L11,$N$28:$N$412)) | P11: =IF(A11=0,"",SUMIF($A$28:$A$412,L11,$P$28:$P$412)) | Q11: =IF(A11=0,"",SUMIF($A$28:$A$412,L11,$Q$28:$Q$412))
L12: =IF(A12=0,"",A12) | N12: =IF(A12=0,"",SUMIF($A$28:$A$412,L12,$N$28:$N$412)) | P12: =IF(A12=0,"",SUMIF($A$28:$A$412,L12,$P$28:$P$412)) | Q12: =IF(A12=0,"",SUMIF($A$28:$A$412,L12,$Q$28:$Q$412))
L13: =IF(A13=0,"",A13) | N13: =IF(A13=0,"",SUMIF($A$28:$A$412,L13,$N$28:$N$412)) | P13: =IF(A13=0,"",SUMIF($A$28:$A$412,L13,$P$28:$P$412)) | Q13: =IF(A13=0,"",SUMIF($A$28:$A$412,L13,$Q$28:$Q$412))
L14: =IF(A14=0,"",A14) | N14: =IF(A14=0,"",SUMIF($A$28:$A$412,L14,$N$28:$N$412)) | P14: =IF(A14=0,"",SUMIF($A$28:$A$412,L14,$P$28:$P$412)) | Q14: =IF(A14=0,"",SUMIF($A$28:$A$412,L14,$Q$28:$Q$412))
L15: =IF(A15=0,"",A15) | N15: =IF(A15=0,"",SUMIF($A$28:$A$412,L15,$N$28:$N$412)) | P15: =IF(A15=0,"",SUMIF($A$28:$A$412,L15,$P$28:$P$412)) | Q15: =IF(A15=0,"",SUMIF($A$28:$A$412,L15,$Q$28:$Q$412))
L16: =IF(A16=0,"",A16) | N16: =IF(A16=0,"",SUMIF($A$28:$A$412,L16,$N$28:$N$412)) | P16: =IF(A16=0,"",SUMIF($A$28:$A$412,L16,$P$28:$P$412)) | Q16: =IF(A16=0,"",SUMIF($A$28:$A$412,L16,$Q$28:$Q$412))
L17: =IF(A17=0,"",A17) | N17: =IF(A17=0,"",SUMIF($A$28:$A$412,L17,$N$28:$N$412)) | P17: =IF(A17=0,"",SUMIF($A$28:$A$412,L17,$P$28:$P$412)) | Q17: =IF(A17=0,"",SUMIF($A$28:$A$412,L17,$Q$28:$Q$412))
L18: =IF(A18=0,"",A18) | N18: =IF(A18=0,"",SUMIF($A$28:$A$412,L18,$N$28:$N$412)) | P18: =IF(A18=0,"",SUMIF($A$28:$A$412,L18,$P$28:$P$412)) | Q18: =IF(A18=0,"",SUMIF($A$28:$A$412,L18,$Q$28:$Q$412))
L19: =IF(A19=0,"",A19) | N19: =IF(A19=0,"",SUMIF($A$28:$A$412,L19,$N$28:$N$412)) | P19: =IF(A19=0,"",SUMIF($A$28:$A$412,L19,$P$28:$P$412)) | Q19: =IF(A19=0,"",SUMIF($A$28:$A$412,L19,$Q$28:$Q$412))
L20: =IF(A20=0,"",A20) | N20: =IF(A20=0,"",SUMIF($A$28:$A$412,L20,$N$28:$N$412)) | P20: =IF(A20=0,"",SUMIF($A$28:$A$412,L20,$P$28:$P$412)) | Q20: =IF(A20=0,"",SUMIF($A$28:$A$412,L20,$Q$28:$Q$412))
L21: =IF(A21=0,"",A21) | N21: =IF(A21=0,"",SUMIF($A$28:$A$412,L21,$N$28:$N$412)) | P21: =IF(A21=0,"",SUMIF($A$28:$A$412,L21,$P$28:$P$412)) | Q21: =IF(A21=0,"",SUMIF($A$28:$A$412,L21,$Q$28:$Q$412))
... L23: =IF(A23=0,"",A23) | N23: =IF(A23=0,"",SUMIF($A$28:$A$412,L23,$N$28:$N$412)) | P23: =IF(A23=0,"",SUMIF($A$28:$A$412,L23,$P$28:$P$412)) | Q23: =IF(A23=0,"",SUMIF($A$28:$A$412,L23,$Q$28:$Q$412))
L24: Total | N24: =SUM(N5:N10) | P24: =SUM(P5:P10) | Q24: =SUM(Q5:Q10)
A26: Data Entry | B26: Data Entry | C26: Data Entry | D26: Data Entry | E26: Data Entry | F26: Data Entry | G26: Data Entry | H26: Data Entry | I26: Data Entry | K26: Calculation | L26: Calculation | M26: Calculation | N26: Calculation | O26: Calculation | P26: Calculation | Q26: Calculation
A27: Impairment Type | B27: Member # | C27: Loan Suffix | D27: Loan Pool | E27: Current Balance | F27: Days Delinquent | G27: Balance at Other Lender (2nd Mortgage and HELOC's) | H27: Collateral Value (for unsecured loans, leave blank) | I27: ="Allowance Provided by "&A1&" (blank cell = Amount at risk calc.)" | J27: Notes: | K27: Member #-Suffix | L27: Total Loans | M27: LTV | N27: Loss Given Default (LGD) | O27: Percent of Amount at Risk applied to Provision | P27: Provision Amount | Q27: Bal Removed from Pools
K28: =B28&"-"&C28 | L28: =E28+G28 | M28: =IF(H28=0,"No Value",L28/H28) | N28: =IF(I28<>"",I28,IF(L28-H28<=0,0,IF(L28-H28>=E28,E28,L28-H28))) | O28: =IF(I28<>"",100%,IF(A28=$A$5,$B$5,IF(A28=$A$6,$B$6,IF(A28=$A$7,$B$7,IF(A28=$A$8,$B$8,IF(A28=$A$9,$B$9,0)))))) | P28: =N28*O28 | Q28: =E28
K29: =B29&"-"&C29 | L29: =E29+G29 | M29: =IF(H29=0,"No Value",L29/H29) | N29: =IF(I29<>"",I29,IF(L29-H29<=0,0,IF(L29-H29>=E29,E29,L29-H29))) | O29: =IF(I29<>"",100%,IF(A29=$A$5,$B$5,IF(A29=$A$6,$B$6,IF(A29=$A$7,$B$7,IF(A29=$A$8,$B$8,IF(A29=$A$9,$B$9,0)))))) | P29: =N29*O29 | Q29: =E29
K30: =B30&"-"&C30 | L30: =E30+G30 | M30: =IF(H30=0,"No Value",L30/H30) | N30: =IF(I30<>"",I30,IF(L30-H30<=0,0,IF(L30-H30>=E30,E30,L30-H30))) | O30: =IF(I30<>"",100%,IF(A30=$A$5,$B$5,IF(A30=$A$6,$B$6,IF(A30=$A$7,$B$7,IF(A30=$A$8,$B$8,IF(A30=$A$9,$B$9,0)))))) | P30: =N30*O30 | Q30: =E30
K31: =B31&"-"&C31 | L31: =E31+G31 | M31: =IF(H31=0,"No Value",L31/H31) | N31: =IF(I31<>"",I31,IF(L31-H31<=0,0,IF(L31-H31>=E31,E31,L31-H31))) | O31: =IF(I31<>"",100%,IF(A31=$A$5,$B$5,IF(A31=$A$6,$B$6,IF(A31=$A$7,$B$7,IF(A31=$A$8,$B$8,IF(A31=$A$9,$B$9,0)))))) | P31: =N31*O31 | Q31: =E31
K32: =B32&"-"&C32 | L32: =E32+G32 | M32: =IF(H32=0,"No Value",L32/H32) | N32: =IF(I32<>"",I32,IF(L32-H32<=0,0,IF(L32-H32>=E32,E32,L32-H32))) | O32: =IF(I32<>"",100%,IF(A32=$A$5,$B$5,IF(A32=$A$6,$B$6,IF(A32=$A$7,$B$7,IF(A32=$A$8,$B$8,IF(A32=$A$9,$B$9,0)))))) | P32: =N32*O32 | Q32: =E32
K33: =B33&"-"&C33 | L33: =E33+G33 | M33: =IF(H33=0,"No Value",L33/H33) | N33: =IF(I33<>"",I33,IF(L33-H33<=0,0,IF(L33-H33>=E33,E33,L33-H33))) | O33: =IF(I33<>"",100%,IF(A33=$A$5,$B$5,IF(A33=$A$6,$B$6,IF(A33=$A$7,$B$7,IF(A33=$A$8,$B$8,IF(A33=$A$9,$B$9,0)))))) | P33: =N33*O33 | Q33: =E33
K34: =B34&"-"&C34 | L34: =E34+G34 | M34: =IF(H34=0,"No Value",L34/H34) | N34: =IF(I34<>"",I34,IF(L34-H34<=0,0,IF(L34-H34>=E34,E34,L34-H34))) | O34: =IF(I34<>"",100%,IF(A34=$A$5,$B$5,IF(A34=$A$6,$B$6,IF(A34=$A$7,$B$7,IF(A34=$A$8,$B$8,IF(A34=$A$9,$B$9,0)))))) | P34: =N34*O34 | Q34: =E34
K35: =B35&"-"&C35 | L35: =E35+G35 | M35: =IF(H35=0,"No Value",L35/H35) | N35: =IF(I35<>"",I35,IF(L35-H35<=0,0,IF(L35-H35>=E35,E35,L35-H35))) | O35: =IF(I35<>"",100%,IF(A35=$A$5,$B$5,IF(A35=$A$6,$B$6,IF(A35=$A$7,$B$7,IF(A35=$A$8,$B$8,IF(A35=$A$9,$B$9,0)))))) | P35: =N35*O35 | Q35: =E35
K36: =B36&"-"&C36 | L36: =E36+G36 | M36: =IF(H36=0,"No Value",L36/H36) | N36: =IF(I36<>"",I36,IF(L36-H36<=0,0,IF(L36-H36>=E36,E36,L36-H36))) | O36: =IF(I36<>"",100%,IF(A36=$A$5,$B$5,IF(A36=$A$6,$B$6,IF(A36=$A$7,$B$7,IF(A36=$A$8,$B$8,IF(A36=$A$9,$B$9,0)))))) | P36: =N36*O36 | Q36: =E36
K37: =B37&"-"&C37 | L37: =E37+G37 | M37: =IF(H37=0,"No Value",L37/H37) | N37: =IF(I37<>"",I37,IF(L37-H37<=0,0,IF(L37-H37>=E37,E37,L37-H37))) | O37: =IF(I37<>"",100%,IF(A37=$A$5,$B$5,IF(A37=$A$6,$B$6,IF(A37=$A$7,$B$7,IF(A37=$A$8,$B$8,IF(A37=$A$9,$B$9,0)))))) | P37: =N37*O37 | Q37: =E37
K38: =B38&"-"&C38 | L38: =E38+G38 | M38: =IF(H38=0,"No Value",L38/H38) | N38: =IF(I38<>"",I38,IF(L38-H38<=0,0,IF(L38-H38>=E38,E38,L38-H38))) | O38: =IF(I38<>"",100%,IF(A38=$A$5,$B$5,IF(A38=$A$6,$B$6,IF(A38=$A$7,$B$7,IF(A38=$A$8,$B$8,IF(A38=$A$9,$B$9,0)))))) | P38: =N38*O38 | Q38: =E38
K39: =B39&"-"&C39 | L39: =E39+G39 | M39: =IF(H39=0,"No Value",L39/H39) | N39: =IF(I39<>"",I39,IF(L39-H39<=0,0,IF(L39-H39>=E39,E39,L39-H39))) | O39: =IF(I39<>"",100%,IF(A39=$A$5,$B$5,IF(A39=$A$6,$B$6,IF(A39=$A$7,$B$7,IF(A39=$A$8,$B$8,IF(A39=$A$9,$B$9,0)))))) | P39: =N39*O39 | Q39: =E39
... K412: =B412&"-"&C412 | L412: =E412+G412 | M412: =IF(H412=0,"No Value",L412/H412) | N412: =IF(I412<>"",I412,IF(L412-H412<=0,0,IF(L412-H412>=E412,E412,L412-H412))) | O412: =IF(I412<>"",100%,IF(A412=$A$5,$B$5,IF(A412=$A$6,$B$6,IF(A412=$A$7,$B$7,IF(A412=$A$8,$B$8,IF(A412=$A$9,$B$9,0)))))) | P412: =N412*O412 | Q412: =E412

Sheet Calc tab
A1: Month Description | B1: Current -87 | C1: Current -84 | D1: Current -81 | E1: Current -78 | F1: Current -75 | G1: Current -72 | H1: Current -69 | I1: Current -66 | J1: Current -63 | K1: Current -60 | L1: Current -57 | M1: Current -54 | N1: Current -51 | O1: Current -48 | P1: Current -45 | Q1: Current -42 | R1: Current -39 | S1: Current -36 | T1: Current -33 | U1: Current -30 | V1: Current -27 | W1: Current -24 | X1: Current -21 | Y1: Current -18 | Z1: Current -15 | AA1: Current -12 | AB1: Current -9 | AC1: Current -6 | AD1: Current -3 | AE1: Current -0
A2: Month # | B2: =IF(C2=3,12,IF(C2=6,3,IF(C2=9,6,IF(C2=12,9)))) | C2: =IF(D2=3,12,IF(D2=6,3,IF(D2=9,6,IF(D2=12,9)))) | D2: =IF(E2=3,12,IF(E2=6,3,IF(E2=9,6,IF(E2=12,9)))) | E2: =IF(F2=3,12,IF(F2=6,3,IF(F2=9,6,IF(F2=12,9)))) | F2: =IF(G2=3,12,IF(G2=6,3,IF(G2=9,6,IF(G2=12,9)))) | G2: =IF(H2=3,12,IF(H2=6,3,IF(H2=9,6,IF(H2=12,9)))) | H2: =IF(I2=3,12,IF(I2=6,3,IF(I2=9,6,IF(I2=12,9)))) | I2: =IF(J2=3,12,IF(J2=6,3,IF(J2=9,6,IF(J2=12,9)))) | ... AD2: =IF(AE2=3,12,IF(AE2=6,3,IF(AE2=9,6,IF(AE2=12,9)))) | AE2: =MONTH(AE6)
A3: Year # | B3: =IF(B2=12,C3-1,C3) | C3: =IF(C2=12,D3-1,D3) | D3: =IF(D2=12,E3-1,E3) | E3: =IF(E2=12,F3-1,F3) | F3: =IF(F2=12,G3-1,G3) | G3: =IF(G2=12,H3-1,H3) | H3: =IF(H2=12,I3-1,I3) | I3: =IF(I2=12,J3-1,J3) | ... AD3: =IF(AD2=12,AE3-1,AE3) | AE3: =YEAR(AE6)
A4: Day# | B4: =IF(B2=6,30,IF(B2=9,30,31)) | C4: =IF(C2=6,30,IF(C2=9,30,31)) | D4: =IF(D2=6,30,IF(D2=9,30,31)) | E4: =IF(E2=6,30,IF(E2=9,30,31)) | F4: =IF(F2=6,30,IF(F2=9,30,31)) | G4: =IF(G2=6,30,IF(G2=9,30,31)) | H4: =IF(H2=6,30,IF(H2=9,30,31)) | I4: =IF(I2=6,30,IF(I2=9,30,31)) | ... AE4: =IF(AE2=6,30,IF(AE2=9,30,31))
A5: Quarter Number | B5: 30 | C5: 29 | D5: 28 | E5: 27 | F5: 26 | G5: 25 | H5: 24 | I5: 23 | J5: 22 | K5: 21 | L5: 20 | M5: 19 | N5: 18 | O5: 17 | P5: 16 | Q5: 15 | R5: 14 | S5: 13 | T5: 12 | U5: 11 | V5: 10 | W5: 9 | X5: 8 | Y5: 7 | Z5: 6 | AA5: 5 | AB5: 4 | AC5: 3 | AD5: 2 | AE5: 1
A6: Loan Balances | B6: =DATE(B3,B2,B4) | C6: =DATE(C3,C2,C4) | D6: =DATE(D3,D2,D4) | E6: =DATE(E3,E2,E4) | F6: =DATE(F3,F2,F4) | G6: =DATE(G3,G2,G4) | H6: =DATE(H3,H2,H4) | I6: =DATE(I3,I2,I4) | ... AD6: =DATE(AD3,AD2,AD4) | AE6: ='Historical Data'!AY8 | AF6: ACL Lifetime Months | AG6: ACL Lifetime Quarters | AH6: Average Balance ACL Lifetime
A7: ='Scale Calculation'!C9 | B7: =IF(B$5>$AG7,"",HLOOKUP(B$6,'Historical Data'!161:174,2,FALSE)) | C7: =IF(C$5>$AG7,"",HLOOKUP(C$6,'Historical Data'!161:174,2,FALSE)) | D7: =IF(D$5>$AG7,"",HLOOKUP(D$6,'Historical Data'!161:174,2,FALSE)) | E7: =IF(E$5>$AG7,"",HLOOKUP(E$6,'Historical Data'!161:174,2,FALSE)) | F7: =IF(F$5>$AG7,"",HLOOKUP(F$6,'Historical Data'!161:174,2,FALSE)) | G7: =IF(G$5>$AG7,"",HLOOKUP(G$6,'Historical Data'!161:174,2,FALSE)) | H7: =IF(H$5>$AG7,"",HLOOKUP(H$6,'Historical Data'!161:174,2,FALSE)) | I7: =IF(I$5>$AG7,"",HLOOKUP(I$6,'Historical Data'!161:174,2,FALSE)) | ... AE7: =IF(AE$5>$AG7,"",HLOOKUP(AE$6,'Historical Data'!161:174,2,FALSE)) | AF7: ='Industry Data'!B3 | AG7: =ROUNDUP(AF7/3,0) | AH7: =SUMIF($B$5:$AE$5,AG7,B24:AE24)/AG7
A8: ='Scale Calculation'!C10 | B8: =IF(B$5>$AG8,"",HLOOKUP(B$6,'Historical Data'!161:174,3,FALSE)) | C8: =IF(C$5>$AG8,"",HLOOKUP(C$6,'Historical Data'!161:174,3,FALSE)) | D8: =IF(D$5>$AG8,"",HLOOKUP(D$6,'Historical Data'!161:174,3,FALSE)) | E8: =IF(E$5>$AG8,"",HLOOKUP(E$6,'Historical Data'!161:174,3,FALSE)) | F8: =IF(F$5>$AG8,"",HLOOKUP(F$6,'Historical Data'!161:174,3,FALSE)) | G8: =IF(G$5>$AG8,"",HLOOKUP(G$6,'Historical Data'!161:174,3,FALSE)) | H8: =IF(H$5>$AG8,"",HLOOKUP(H$6,'Historical Data'!161:174,3,FALSE)) | I8: =IF(I$5>$AG8,"",HLOOKUP(I$6,'Historical Data'!161:174,3,FALSE)) | ... AE8: =IF(AE$5>$AG8,"",HLOOKUP(AE$6,'Historical Data'!161:174,3,FALSE)) | AF8: ='Industry Data'!B4 | AG8: =ROUNDUP(AF8/3,0) | AH8: =SUMIF($B$5:$AE$5,AG8,B25:AE25)/AG8
A9: ='Scale Calculation'!C11 | B9: =IF(B$5>$AG9,"",HLOOKUP(B$6,'Historical Data'!161:174,4,FALSE)) | C9: =IF(C$5>$AG9,"",HLOOKUP(C$6,'Historical Data'!161:174,4,FALSE)) | D9: =IF(D$5>$AG9,"",HLOOKUP(D$6,'Historical Data'!161:174,4,FALSE)) | E9: =IF(E$5>$AG9,"",HLOOKUP(E$6,'Historical Data'!161:174,4,FALSE)) | F9: =IF(F$5>$AG9,"",HLOOKUP(F$6,'Historical Data'!161:174,4,FALSE)) | G9: =IF(G$5>$AG9,"",HLOOKUP(G$6,'Historical Data'!161:174,4,FALSE)) | H9: =IF(H$5>$AG9,"",HLOOKUP(H$6,'Historical Data'!161:174,4,FALSE)) | I9: =IF(I$5>$AG9,"",HLOOKUP(I$6,'Historical Data'!161:174,4,FALSE)) | ... AE9: =IF(AE$5>$AG9,"",HLOOKUP(AE$6,'Historical Data'!161:174,4,FALSE)) | AF9: ='Industry Data'!B5 | AG9: =ROUNDUP(AF9/3,0) | AH9: =SUMIF($B$5:$AE$5,AG9,B26:AE26)/AG9
A10: ='Scale Calculation'!C12 | B10: =IF(B$5>$AG10,"",HLOOKUP(B$6,'Historical Data'!161:174,5,FALSE)) | C10: =IF(C$5>$AG10,"",HLOOKUP(C$6,'Historical Data'!161:174,5,FALSE)) | D10: =IF(D$5>$AG10,"",HLOOKUP(D$6,'Historical Data'!161:174,5,FALSE)) | E10: =IF(E$5>$AG10,"",HLOOKUP(E$6,'Historical Data'!161:174,5,FALSE)) | F10: =IF(F$5>$AG10,"",HLOOKUP(F$6,'Historical Data'!161:174,5,FALSE)) | G10: =IF(G$5>$AG10,"",HLOOKUP(G$6,'Historical Data'!161:174,5,FALSE)) | H10: =IF(H$5>$AG10,"",HLOOKUP(H$6,'Historical Data'!161:174,5,FALSE)) | I10: =IF(I$5>$AG10,"",HLOOKUP(I$6,'Historical Data'!161:174,5,FALSE)) | ... AE10: =IF(AE$5>$AG10,"",HLOOKUP(AE$6,'Historical Data'!161:174,5,FALSE)) | AF10: ='Industry Data'!B6 | AG10: =ROUNDUP(AF10/3,0) | AH10: =SUMIF($B$5:$AE$5,AG10,B27:AE27)/AG10
A11: ='Scale Calculation'!C13 | B11: =IF(B$5>$AG11,"",HLOOKUP(B$6,'Historical Data'!161:174,6,FALSE)) | C11: =IF(C$5>$AG11,"",HLOOKUP(C$6,'Historical Data'!161:174,6,FALSE)) | D11: =IF(D$5>$AG11,"",HLOOKUP(D$6,'Historical Data'!161:174,6,FALSE)) | E11: =IF(E$5>$AG11,"",HLOOKUP(E$6,'Historical Data'!161:174,6,FALSE)) | F11: =IF(F$5>$AG11,"",HLOOKUP(F$6,'Historical Data'!161:174,6,FALSE)) | G11: =IF(G$5>$AG11,"",HLOOKUP(G$6,'Historical Data'!161:174,6,FALSE)) | H11: =IF(H$5>$AG11,"",HLOOKUP(H$6,'Historical Data'!161:174,6,FALSE)) | I11: =IF(I$5>$AG11,"",HLOOKUP(I$6,'Historical Data'!161:174,6,FALSE)) | ... AE11: =IF(AE$5>$AG11,"",HLOOKUP(AE$6,'Historical Data'!161:174,6,FALSE)) | AF11: ='Industry Data'!B7 | AG11: =ROUNDUP(AF11/3,0) | AH11: =SUMIF($B$5:$AE$5,AG11,B28:AE28)/AG11
A12: ='Scale Calculation'!C14 | B12: =IF(B$5>$AG12,"",HLOOKUP(B$6,'Historical Data'!161:174,7,FALSE)) | C12: =IF(C$5>$AG12,"",HLOOKUP(C$6,'Historical Data'!161:174,7,FALSE)) | D12: =IF(D$5>$AG12,"",HLOOKUP(D$6,'Historical Data'!161:174,7,FALSE)) | E12: =IF(E$5>$AG12,"",HLOOKUP(E$6,'Historical Data'!161:174,7,FALSE)) | F12: =IF(F$5>$AG12,"",HLOOKUP(F$6,'Historical Data'!161:174,7,FALSE)) | G12: =IF(G$5>$AG12,"",HLOOKUP(G$6,'Historical Data'!161:174,7,FALSE)) | H12: =IF(H$5>$AG12,"",HLOOKUP(H$6,'Historical Data'!161:174,7,FALSE)) | I12: =IF(I$5>$AG12,"",HLOOKUP(I$6,'Historical Data'!161:174,7,FALSE)) | ... AE12: =IF(AE$5>$AG12,"",HLOOKUP(AE$6,'Historical Data'!161:174,7,FALSE)) | AF12: ='Industry Data'!B8 | AG12: =ROUNDUP(AF12/3,0) | AH12: =SUMIF($B$5:$AE$5,AG12,B29:AE29)/AG12
A13: ='Scale Calculation'!C15 | B13: =IF(B$5>$AG13,"",HLOOKUP(B$6,'Historical Data'!161:174,8,FALSE)) | C13: =IF(C$5>$AG13,"",HLOOKUP(C$6,'Historical Data'!161:174,8,FALSE)) | D13: =IF(D$5>$AG13,"",HLOOKUP(D$6,'Historical Data'!161:174,8,FALSE)) | E13: =IF(E$5>$AG13,"",HLOOKUP(E$6,'Historical Data'!161:174,8,FALSE)) | F13: =IF(F$5>$AG13,"",HLOOKUP(F$6,'Historical Data'!161:174,8,FALSE)) | G13: =IF(G$5>$AG13,"",HLOOKUP(G$6,'Historical Data'!161:174,8,FALSE)) | H13: =IF(H$5>$AG13,"",HLOOKUP(H$6,'Historical Data'!161:174,8,FALSE)) | I13: =IF(I$5>$AG13,"",HLOOKUP(I$6,'Historical Data'!161:174,8,FALSE)) | ... AE13: =IF(AE$5>$AG13,"",HLOOKUP(AE$6,'Historical Data'!161:174,8,FALSE)) | AF13: ='Industry Data'!B9 | AG13: =ROUNDUP(AF13/3,0) | AH13: =SUMIF($B$5:$AE$5,AG13,B30:AE30)/AG13
A14: ='Scale Calculation'!C16 | B14: =IF(B$5>$AG14,"",HLOOKUP(B$6,'Historical Data'!161:174,9,FALSE)) | C14: =IF(C$5>$AG14,"",HLOOKUP(C$6,'Historical Data'!161:174,9,FALSE)) | D14: =IF(D$5>$AG14,"",HLOOKUP(D$6,'Historical Data'!161:174,9,FALSE)) | E14: =IF(E$5>$AG14,"",HLOOKUP(E$6,'Historical Data'!161:174,9,FALSE)) | F14: =IF(F$5>$AG14,"",HLOOKUP(F$6,'Historical Data'!161:174,9,FALSE)) | G14: =IF(G$5>$AG14,"",HLOOKUP(G$6,'Historical Data'!161:174,9,FALSE)) | H14: =IF(H$5>$AG14,"",HLOOKUP(H$6,'Historical Data'!161:174,9,FALSE)) | I14: =IF(I$5>$AG14,"",HLOOKUP(I$6,'Historical Data'!161:174,9,FALSE)) | ... AE14: =IF(AE$5>$AG14,"",HLOOKUP(AE$6,'Historical Data'!161:174,9,FALSE)) | AF14: ='Industry Data'!B10 | AG14: =ROUNDUP(AF14/3,0) | AH14: =SUMIF($B$5:$AE$5,AG14,B31:AE31)/AG14
A15: ='Scale Calculation'!C17 | B15: =IF(B$5>$AG15,"",HLOOKUP(B$6,'Historical Data'!161:174,10,FALSE)) | C15: =IF(C$5>$AG15,"",HLOOKUP(C$6,'Historical Data'!161:174,10,FALSE)) | D15: =IF(D$5>$AG15,"",HLOOKUP(D$6,'Historical Data'!161:174,10,FALSE)) | E15: =IF(E$5>$AG15,"",HLOOKUP(E$6,'Historical Data'!161:174,10,FALSE)) | F15: =IF(F$5>$AG15,"",HLOOKUP(F$6,'Historical Data'!161:174,10,FALSE)) | G15: =IF(G$5>$AG15,"",HLOOKUP(G$6,'Historical Data'!161:174,10,FALSE)) | H15: =IF(H$5>$AG15,"",HLOOKUP(H$6,'Historical Data'!161:174,10,FALSE)) | I15: =IF(I$5>$AG15,"",HLOOKUP(I$6,'Historical Data'!161:174,10,FALSE)) | ... AE15: =IF(AE$5>$AG15,"",HLOOKUP(AE$6,'Historical Data'!161:174,10,FALSE)) | AF15: ='Industry Data'!B11 | AG15: =ROUNDUP(AF15/3,0) | AH15: =SUMIF($B$5:$AE$5,AG15,B32:AE32)/AG15
A16: ='Scale Calculation'!C18 | B16: =IF(B$5>$AG16,"",HLOOKUP(B$6,'Historical Data'!161:174,11,FALSE)) | C16: =IF(C$5>$AG16,"",HLOOKUP(C$6,'Historical Data'!161:174,11,FALSE)) | D16: =IF(D$5>$AG16,"",HLOOKUP(D$6,'Historical Data'!161:174,11,FALSE)) | E16: =IF(E$5>$AG16,"",HLOOKUP(E$6,'Historical Data'!161:174,11,FALSE)) | F16: =IF(F$5>$AG16,"",HLOOKUP(F$6,'Historical Data'!161:174,11,FALSE)) | G16: =IF(G$5>$AG16,"",HLOOKUP(G$6,'Historical Data'!161:174,11,FALSE)) | H16: =IF(H$5>$AG16,"",HLOOKUP(H$6,'Historical Data'!161:174,11,FALSE)) | I16: =IF(I$5>$AG16,"",HLOOKUP(I$6,'Historical Data'!161:174,11,FALSE)) | ... AE16: =IF(AE$5>$AG16,"",HLOOKUP(AE$6,'Historical Data'!161:174,11,FALSE)) | AF16: ='Industry Data'!B12 | AG16: =ROUNDUP(AF16/3,0) | AH16: =SUMIF($B$5:$AE$5,AG16,B33:AE33)/AG16
A17: ='Scale Calculation'!C19 | B17: =IF(B$5>$AG17,"",HLOOKUP(B$6,'Historical Data'!161:174,12,FALSE)) | C17: =IF(C$5>$AG17,"",HLOOKUP(C$6,'Historical Data'!161:174,12,FALSE)) | D17: =IF(D$5>$AG17,"",HLOOKUP(D$6,'Historical Data'!161:174,12,FALSE)) | E17: =IF(E$5>$AG17,"",HLOOKUP(E$6,'Historical Data'!161:174,12,FALSE)) | F17: =IF(F$5>$AG17,"",HLOOKUP(F$6,'Historical Data'!161:174,12,FALSE)) | G17: =IF(G$5>$AG17,"",HLOOKUP(G$6,'Historical Data'!161:174,12,FALSE)) | H17: =IF(H$5>$AG17,"",HLOOKUP(H$6,'Historical Data'!161:174,12,FALSE)) | I17: =IF(I$5>$AG17,"",HLOOKUP(I$6,'Historical Data'!161:174,12,FALSE)) | ... AE17: =IF(AE$5>$AG17,"",HLOOKUP(AE$6,'Historical Data'!161:174,12,FALSE)) | AF17: ='Industry Data'!B13 | AG17: =ROUNDUP(AF17/3,0) | AH17: =SUMIF($B$5:$AE$5,AG17,B34:AE34)/AG17
A18: ='Scale Calculation'!C20 | B18: =IF(B$5>$AG18,"",HLOOKUP(B$6,'Historical Data'!161:174,13,FALSE)) | C18: =IF(C$5>$AG18,"",HLOOKUP(C$6,'Historical Data'!161:174,13,FALSE)) | D18: =IF(D$5>$AG18,"",HLOOKUP(D$6,'Historical Data'!161:174,13,FALSE)) | E18: =IF(E$5>$AG18,"",HLOOKUP(E$6,'Historical Data'!161:174,13,FALSE)) | F18: =IF(F$5>$AG18,"",HLOOKUP(F$6,'Historical Data'!161:174,13,FALSE)) | G18: =IF(G$5>$AG18,"",HLOOKUP(G$6,'Historical Data'!161:174,13,FALSE)) | H18: =IF(H$5>$AG18,"",HLOOKUP(H$6,'Historical Data'!161:174,13,FALSE)) | I18: =IF(I$5>$AG18,"",HLOOKUP(I$6,'Historical Data'!161:174,13,FALSE)) | ... AE18: =IF(AE$5>$AG18,"",HLOOKUP(AE$6,'Historical Data'!161:174,13,FALSE)) | AF18: ='Industry Data'!B14 | AG18: =ROUNDUP(AF18/3,0) | AH18: =SUMIF($B$5:$AE$5,AG18,B35:AE35)/AG18
A19: ='Scale Calculation'!C21 | B19: =IF(B$5>$AG19,"",HLOOKUP(B$6,'Historical Data'!161:174,14,FALSE)) | C19: =IF(C$5>$AG19,"",HLOOKUP(C$6,'Historical Data'!161:174,14,FALSE)) | D19: =IF(D$5>$AG19,"",HLOOKUP(D$6,'Historical Data'!161:174,14,FALSE)) | E19: =IF(E$5>$AG19,"",HLOOKUP(E$6,'Historical Data'!161:174,14,FALSE)) | F19: =IF(F$5>$AG19,"",HLOOKUP(F$6,'Historical Data'!161:174,14,FALSE)) | G19: =IF(G$5>$AG19,"",HLOOKUP(G$6,'Historical Data'!161:174,14,FALSE)) | H19: =IF(H$5>$AG19,"",HLOOKUP(H$6,'Historical Data'!161:174,14,FALSE)) | I19: =IF(I$5>$AG19,"",HLOOKUP(I$6,'Historical Data'!161:174,14,FALSE)) | ... AE19: =IF(AE$5>$AG19,"",HLOOKUP(AE$6,'Historical Data'!161:174,14,FALSE)) | AF19: ='Industry Data'!B15 | AG19: =ROUNDUP(AF19/3,0) | AH19: =SUMIF($B$5:$AE$5,AG19,B36:AE36)/AG19
A20: Total Loans | B20: =SUM(B7:B19) | C20: =SUM(C7:C19) | D20: =SUM(D7:D19) | E20: =SUM(E7:E19) | F20: =SUM(F7:F19) | G20: =SUM(G7:G19) | H20: =SUM(H7:H19) | I20: =SUM(I7:I19) | ... AE20: =SUM(AE7:AE19) | AG20: =ROUNDUP(AF20/3,0)
A23: Cumlative Loan Balance Totals | B23: =B6 | C23: =C6 | D23: =D6 | E23: =E6 | F23: =F6 | G23: =G6 | H23: =H6 | I23: =I6 | ... AE23: =AE6
A24: =A7 | B24: =IFERROR(B7+C24,0) | C24: =IFERROR(C7+D24,0) | D24: =IFERROR(D7+E24,0) | E24: =IFERROR(E7+F24,0) | F24: =IFERROR(F7+G24,0) | G24: =IFERROR(G7+H24,0) | H24: =IFERROR(H7+I24,0) | I24: =IFERROR(I7+J24,0) | ... AE24: =IFERROR(AE7+AF24,0)
A25: =A8 | B25: =IFERROR(B8+C25,0) | C25: =IFERROR(C8+D25,0) | D25: =IFERROR(D8+E25,0) | E25: =IFERROR(E8+F25,0) | F25: =IFERROR(F8+G25,0) | G25: =IFERROR(G8+H25,0) | H25: =IFERROR(H8+I25,0) | I25: =IFERROR(I8+J25,0) | ... AE25: =IFERROR(AE8+AF25,0)
A26: =A9 | B26: =IFERROR(B9+C26,0) | C26: =IFERROR(C9+D26,0) | D26: =IFERROR(D9+E26,0) | E26: =IFERROR(E9+F26,0) | F26: =IFERROR(F9+G26,0) | G26: =IFERROR(G9+H26,0) | H26: =IFERROR(H9+I26,0) | I26: =IFERROR(I9+J26,0) | ... AE26: =IFERROR(AE9+AF26,0)
A27: =A10 | B27: =IFERROR(B10+C27,0) | C27: =IFERROR(C10+D27,0) | D27: =IFERROR(D10+E27,0) | E27: =IFERROR(E10+F27,0) | F27: =IFERROR(F10+G27,0) | G27: =IFERROR(G10+H27,0) | H27: =IFERROR(H10+I27,0) | I27: =IFERROR(I10+J27,0) | ... AE27: =IFERROR(AE10+AF27,0)
A28: =A11 | B28: =IFERROR(B11+C28,0) | C28: =IFERROR(C11+D28,0) | D28: =IFERROR(D11+E28,0) | E28: =IFERROR(E11+F28,0) | F28: =IFERROR(F11+G28,0) | G28: =IFERROR(G11+H28,0) | H28: =IFERROR(H11+I28,0) | I28: =IFERROR(I11+J28,0) | ... AE28: =IFERROR(AE11+AF28,0)
A29: =A12 | B29: =IFERROR(B12+C29,0) | C29: =IFERROR(C12+D29,0) | D29: =IFERROR(D12+E29,0) | E29: =IFERROR(E12+F29,0) | F29: =IFERROR(F12+G29,0) | G29: =IFERROR(G12+H29,0) | H29: =IFERROR(H12+I29,0) | I29: =IFERROR(I12+J29,0) | ... AE29: =IFERROR(AE12+AF29,0)
A30: =A13 | B30: =IFERROR(B13+C30,0) | C30: =IFERROR(C13+D30,0) | D30: =IFERROR(D13+E30,0) | E30: =IFERROR(E13+F30,0) | F30: =IFERROR(F13+G30,0) | G30: =IFERROR(G13+H30,0) | H30: =IFERROR(H13+I30,0) | I30: =IFERROR(I13+J30,0) | ... AE30: =IFERROR(AE13+AF30,0)
A31: =A14 | B31: =IFERROR(B14+C31,0) | C31: =IFERROR(C14+D31,0) | D31: =IFERROR(D14+E31,0) | E31: =IFERROR(E14+F31,0) | F31: =IFERROR(F14+G31,0) | G31: =IFERROR(G14+H31,0) | H31: =IFERROR(H14+I31,0) | I31: =IFERROR(I14+J31,0) | ... AE31: =IFERROR(AE14+AF31,0)
A32: =A15 | B32: =IFERROR(B15+C32,0) | C32: =IFERROR(C15+D32,0) | D32: =IFERROR(D15+E32,0) | E32: =IFERROR(E15+F32,0) | F32: =IFERROR(F15+G32,0) | G32: =IFERROR(G15+H32,0) | H32: =IFERROR(H15+I32,0) | I32: =IFERROR(I15+J32,0) | ... AE32: =IFERROR(AE15+AF32,0)
A33: =A16 | B33: =IFERROR(B16+C33,0) | C33: =IFERROR(C16+D33,0) | D33: =IFERROR(D16+E33,0) | E33: =IFERROR(E16+F33,0) | F33: =IFERROR(F16+G33,0) | G33: =IFERROR(G16+H33,0) | H33: =IFERROR(H16+I33,0) | I33: =IFERROR(I16+J33,0) | ... AE33: =IFERROR(AE16+AF33,0)
A34: =A17 | B34: =IFERROR(B17+C34,0) | C34: =IFERROR(C17+D34,0) | D34: =IFERROR(D17+E34,0) | E34: =IFERROR(E17+F34,0) | F34: =IFERROR(F17+G34,0) | G34: =IFERROR(G17+H34,0) | H34: =IFERROR(H17+I34,0) | I34: =IFERROR(I17+J34,0) | ... AE34: =IFERROR(AE17+AF34,0)
A35: =A18 | B35: =IFERROR(B18+C35,0) | C35: =IFERROR(C18+D35,0) | D35: =IFERROR(D18+E35,0) | E35: =IFERROR(E18+F35,0) | F35: =IFERROR(F18+G35,0) | G35: =IFERROR(G18+H35,0) | H35: =IFERROR(H18+I35,0) | I35: =IFERROR(I18+J35,0) | ... AE35: =IFERROR(AE18+AF35,0)
A36: =A19 | B36: =IFERROR(B19+C36,0) | C36: =IFERROR(C19+D36,0) | D36: =IFERROR(D19+E36,0) | E36: =IFERROR(E19+F36,0) | F36: =IFERROR(F19+G36,0) | G36: =IFERROR(G19+H36,0) | H36: =IFERROR(H19+I36,0) | I36: =IFERROR(I19+J36,0) | ... AE36: =IFERROR(AE19+AF36,0)
A37: Total Loans | B37: =SUM(B24:B36) | C37: =SUM(C24:C36) | D37: =SUM(D24:D36) | E37: =SUM(E24:E36) | F37: =SUM(F24:F36) | G37: =SUM(G24:G36) | H37: =SUM(H24:H36) | I37: =SUM(I24:I36) | ... AE37: =SUM(AE24:AE36)
A40: Net Charge offs | B40: =B6 | C40: =C6 | D40: =D6 | E40: =E6 | F40: =F6 | G40: =G6 | H40: =H6 | I40: =I6 | ... AE40: =AE6 | AF40: ACL Lifetime Months | AG40: ACL Lifetime Quarters | AH40: Total ACL Lifetime Net Charge off | AI40: ACL Loss Rate
A41: =A7 | B41: =IF(B7="","",B58) | C41: =IF(C7="","",C58) | D41: =IF(D7="","",D58) | E41: =IF(E7="","",E58) | F41: =IF(F7="","",F58) | G41: =IF(G7="","",G58) | H41: =IF(H7="","",H58) | I41: =IF(I7="","",I58) | ... AE41: =IF(AE7="","",AE58) | AF41: =AF58 | AG41: =AG58 | AH41: =AH58 | AI41: =AI58
A42: =A8 | B42: =IF(B8="","",B59) | C42: =IF(C8="","",C59) | D42: =IF(D8="","",D59) | E42: =IF(E8="","",E59) | F42: =IF(F8="","",F59) | G42: =IF(G8="","",G59) | H42: =IF(H8="","",H59) | I42: =IF(I8="","",I59) | ... AE42: =IF(AE8="","",AE59) | AF42: =AF59 | AG42: =AG59 | AH42: =AH59 | AI42: =AI59
A43: =A9 | B43: =IF(B9="","",B60) | C43: =IF(C9="","",C60) | D43: =IF(D9="","",D60) | E43: =IF(E9="","",E60) | F43: =IF(F9="","",F60) | G43: =IF(G9="","",G60) | H43: =IF(H9="","",H60) | I43: =IF(I9="","",I60) | ... AE43: =IF(AE9="","",AE60) | AF43: =AF60 | AG43: =AG60 | AH43: =AH60 | AI43: =AI60
A44: =A10 | B44: =IF(B10="","",B61) | C44: =IF(C10="","",C61) | D44: =IF(D10="","",D61) | E44: =IF(E10="","",E61) | F44: =IF(F10="","",F61) | G44: =IF(G10="","",G61) | H44: =IF(H10="","",H61) | I44: =IF(I10="","",I61) | ... AE44: =IF(AE10="","",AE61) | AF44: =AF61 | AG44: =AG61 | AH44: =AH61 | AI44: =AI61
...

Sheet Cover-Vizo
A8: CECL Allowance Report
A9: Using SCALE Methodology
A10: =Cover!A13
A11: =Cover!A17
B12: The following analysis and all parts thereof (‘analysis’) are based upon information obtained by Vizo Financial Corporate Credit Union (Vizo Financial) from the credit union that is subject of this analysis and other sources that Vizo Financial believes to be reliable and utilized in models using methods and assumptions which Vizo Financial believes to be reasonable. However, actual performance compared to estimated performance of the subject credit union may be different and cannot be guaranteed. This analysis is for informational purposes only and is intended only for the use of the subject credit union. The analysis does not constitute either legal or tax advice. All reports are confidential.
B32: © 2025 TCT Risk Solutions

Sheet Executive Summary-Vizo
A1: CECL Allowances for Credit Losses (ACL) Calculation
A2: ="Prepared For "&'Cover-Vizo'!A10
A3: ="Quarter Ended "&TEXT('Cover-Vizo'!A11,"m/d/yyyy")
B7: Executive Summary
B9: Current ACL | C9: ='Calc tab'!AE6
B10: ='Scale Calculation-Vizo'!O27 | C10: ='Scale Calculation-Vizo'!S27
B11: ='Scale Calculation-Vizo'!O28 | C11: ='Scale Calculation-Vizo'!S28
B12: ='Scale Calculation-Vizo'!O29 | C12: ='Scale Calculation-Vizo'!S29
B13: ='Scale Calculation-Vizo'!O30 | C13: ='Scale Calculation-Vizo'!S30
B15: Prior ACL | C15: =OFFSET('Calc tab'!AE6,0,-1)
B16: Total Expected Losses on Loans | C16: =OFFSET('Historical Data'!AZ2,0,-1)
